<?xml version="1.0" ?>
<!-- =================================================================================== -->
<!-- |    This document was autogenerated by xacro from blocks.urdf.xacro              | -->
<!-- |    EDITING THIS FILE BY HAND IS NOT RECOMMENDED                                 | -->
<!-- =================================================================================== -->
<robot name="blocks" xmlns:xacro="http://www.ros.org/wiki/xacro">
  <material name="red">
    <color rgba="1 0 0 1"/>
  </material>
  <material name="green">
    <color rgba="0 1 0 1"/>
  </material>
  <material name="blue">
    <color rgba="0 0 1 1"/>
  </material>
  <link name="world"/>
  <joint name="world_block1_joint" type="fixed">
    <parent link="world"/>
    <child link="block1"/>
  </joint>
  <link name="block1">
    <visual>
      <geometry>
        <box size="0.8 0.8 0.8"/>
      </geometry>
      <origin xyz="0 0 0"/>
      <material name="red"/>
    </visual>
  </link>
  <joint name="block1_block2_joint" type="continuous">
    <parent link="block1"/>
    <child link="block2"/>
    <origin xyz="1 0 0"/>
  </joint>
  <link name="block2">
    <visual>
      <geometry>
        <box size="0.4 0.4 0.4"/>
      </geometry>
      <origin xyz="0 0 0"/>
      <material name="green"/>
    </visual>
  </link>
  <joint name="block2_block3_joint" type="continuous">
    <parent link="block2"/>
    <child link="block3"/>
    <origin xyz="1 0 0"/>
  </joint>
  <link name="block3">
    <visual>
      <geometry>
        <box size="0.2 0.2 0.2"/>
      </geometry>
      <origin xyz="0 0 0"/>
      <material name="blue"/>
    </visual>
  </link>
</robot>
